Workbook

Sheet RESUMO
A1: MARCAS | H1: De | I1: Até | J1: Frete | K1: Valor min | L1: Valor Max
A2: BOMBER | C2: PREÇO DE VENDA | D2: 599 | H2: 0 | I2: 0.3 | J2: 11.97 | K2: 79 | L2: 99.99
A3: POSITIVO | H3: 0.3 | I3: 0.5 | J3: 12.87 | K3: 79 | L3: 99.99
A4: BRASTEMP | C4: COMISSÃO | D4: 0.1 | E4: =D2*D4 -> 59.9 | H4: 0.5 | I4: 1 | J4: 13.47 | K4: 79 | L4: 99.99
A5: VENTISOL | C5: FRETE | D5: =D2*5% -> 29.95 | E5: =D5 -> 29.95 | H5: 1 | I5: 2 | J5: 14.07 | K5: 79 | L5: 99.99
A6: AOC | C6: EMBALAGEM | D6: 0 | E6: =D6 -> 0 | H6: 2 | I6: 3 | J6: 14.97 | K6: 79 | L6: 99.99
A7: PHILIPS | C7: MAGIS | D7: 0 | E7: =D7 -> 0 | H7: 3 | I7: 4 | J7: 16.17 | K7: 79 | L7: 99.99
A8: LG | C8: FINANCEIRO | D8: 0 | E8: =D21*D8 -> 0 | H8: 4 | I8: 5 | J8: 17.07 | K8: 79 | L8: 99.99
A9: EFL | C9: IMPOSTO + CUSTO FIXO | D9: 0 | E9: =D9*D2 -> 0 | H9: 5 | I9: 9 | J9: 26.67 | K9: 79 | L9: 99.99
A10: THUNDEROBOT | C10: COMISSÃO | D10: 0 | E10: =D10*D21 -> 0 | H10: 9 | I10: 13 | J10: 39.57 | K10: 79 | L10: 99.99
A11: DAZZ | C11: REBATE | D11: 0 | E11: 0 | H11: 13 | I11: 17 | J11: 44.07 | K11: 79 | L11: 99.99
A12: MAXPRINT | C12: INDICE DE RMA | D12: 0 | E12: =D21*D12 -> 0 | H12: 0 | I12: 0.3 | J12: 13.97 | K12: 100 | L12: 119.99
A13: MONDIAL | C13: COLETA | D13: 0 | E13: =D13*D21 -> 0 | H13: 0.3 | I13: 0.5 | J13: 15.01 | K13: 100 | L13: 119.99
A14: AMAZON | H14: 0.5 | I14: 1 | J14: 15.71 | K14: 100 | L14: 119.99
A15: BRITANIA | C15: VALOR LIQUIDO | D15: =D2-E4-D5-D6-D7-E8-E9-E10-E12-E11+D11 -> 509.15 | H15: 1 | I15: 2 | J15: 16.41 | K15: 100 | L15: 119.99
A16: TARGUS | C16: MARGEM VALOR | D16: =D15-D21 -> 210.15 | E16: =D16*50 -> 10507.5 | H16: 2 | I16: 3 | J16: 17.47 | K16: 100 | L16: 119.99
A17: MALLORY | C17: MARGEM DA VENDA | D17: =D16/D2 -> 0.35083472 | E17: =D16 -> 210.15 | H17: 3 | I17: 4 | J17: 18.87 | K17: 100 | L17: 119.99
A18: COLORMAQ | C18: MARGEM LIQUIDA | D18: =D16/D21 -> 0.70284281 | H18: 4 | I18: 5 | J18: 19.92 | K18: 100 | L18: 119.99
A19: PHILCO | H19: 5 | I19: 9 | J19: 31.12 | K19: 100 | L19: 119.99
A20: VAIO | H20: 9 | I20: 13 | J20: 46.17 | K20: 100 | L20: 119.99
A21: FISCHER | C21: CUSTO | D21: 299 | E21: =D21*1.2 -> 358.8 | H21: 13 | I21: 17 | J21: 51.42 | K21: 100 | L21: 119.99
A22: INSTA360 | D22: 3 | H22: 17 | I22: 23 | J22: 60.17 | K22: 100 | L22: 119.99
A23: TAIFF | C23: CUSTO IDEAL | D23: =D15*0.8 -> 407.32 | H23: 0 | I23: 0.3 | J23: 15.96 | K23: 120 | L23: 149.99
A24: MIDEA | H24: 0.3 | I24: 0.5 | J24: 17.16 | K24: 120 | L24: 149.99
A25: CONSUL | H25: 0.5 | I25: 1 | J25: 17.95 | K25: 120 | L25: 149.99
A26: NAUTIKA | H26: 1 | I26: 2 | J26: 18.76 | K26: 120 | L26: 149.99
A27: ECOFLEX | H27: 2 | I27: 3 | J27: 19.96 | K27: 120 | L27: 149.99
A28: GAZIN | H28: 3 | I28: 4 | J28: 21.56 | K28: 120 | L28: 149.99
A29: BLACKDECKER | H29: 4 | I29: 5 | J29: 22.76 | K29: 120 | L29: 149.99
A30: SEMP | H30: 5 | I30: 9 | J30: 35.56 | K30: 120 | L30: 149.99
H31: 9 | I31: 13 | J31: 52.76 | K31: 120 | L31: 149.99
H32: 13 | I32: 17 | J32: 58.76 | K32: 120 | L32: 149.99
H33: 17 | I33: 23 | J33: 68.76 | K33: 120 | L33: 149.99
H34: 23 | I34: 30 | J34: 79.16 | K34: 120 | L34: 149.99
H35: 0 | I35: 0.3 | J35: 17.95 | K35: 150 | L35: 199.99
H36: 0.3 | I36: 0.5 | J36: 19.3 | K36: 150 | L36: 199.99
H37: 0.5 | I37: 1 | J37: 20.2 | K37: 150 | L37: 199.99
H38: 1 | I38: 2 | J38: 21.1 | K38: 150 | L38: 199.99
H39: 2 | I39: 3 | J39: 22.45 | K39: 150 | L39: 199.99
H40: 3 | I40: 4 | J40: 24.25 | K40: 150 | L40: 199.99
...

Sheet INIST
A1: MARCA | B1: SKU | C1: CUSTO | D1: PEMI | E1: IMPOSTO | F1: VERBA | G1: AUTO | H1: CLASSICO | I1: COMISSÃO | J1: FRETE | K1: PROMO | L1: MARGEM | M1: PREMIUM | N1: COMISSAO | O1: FRETE | P1: PROMO | Q1: MARGEM
A2: PHILCO | B2: PHILCO-PAS26P-BIV | C2: 499.43 | D2: 4 | E2: 0.04 | F2: 0 | G2: 2 | H2: 575 | I2: 0.11 | J2: {=IF(H2<12.5, H2/2, IF(H2<29, 6.25, IF(H2<50, 6.5, IF(H2<79, 6.75, VALUE(SUBSTITUTE( INDEX(RESUMO!$J$2:$J$100, MATCH(1, (D2>=RESUMO!$H$2:$H$100)*(D2<=RESUMO!$I$2:$I$100)*(H2>=RESUMO!$K$2:$K$100)*(H2<=RESUMO!$L$2:$L$100), 0)), "R$ ", "")) ))))} -> 26.95 | K2: 0 | L2: =S2/H2 -> -0.060186435 | M2: 709.25 | N2: 0.16 | O2: {=IF(M2<12.5, 0, IF(M2<29, 6.25, IF(M2<50, 6.5, IF(M2<79, 6.75, VALUE(SUBSTITUTE( INDEX(RESUMO!$J$2:$J$100, MATCH(1, (D2>=RESUMO!$H$2:$H$100)*(D2<=RESUMO!$I$2:$I$100)*(M2>=RESUMO!$K$2:$K$100)*(M2<=RESUMO!$L$2:$L$100), 0)), "R$ ", "")) ))))} -> 26.95 | P2: 0 | Q2: =U2/M2 -> 0.069669087 | R2: =(H2-(H2*I2)-J2-(C2*E2)+K2) -> 464.8228 | S2: =R2-(C2-F2) -> -34.6072 | T2: =(M2-(M2*N2)-O2-(C2*E2)+P2) -> 548.8428 | U2: =T2-(C2-F2) -> 49.4128
A3: BRITANIA | B3: BRITANIA-BAS1500V-220V | C3: 130.51 | D3: 2 | E3: 0.04 | F3: 0 | G3: 2 | H3: 187.5 | I3: 0.11 | J3: {=IF(H3<12.5, H3/2, IF(H3<29, 6.25, IF(H3<50, 6.5, IF(H3<79, 6.75, VALUE(SUBSTITUTE( INDEX(RESUMO!$J$2:$J$100, MATCH(1, (D3>=RESUMO!$H$2:$H$100)*(D3<=RESUMO!$I$2:$I$100)*(H3>=RESUMO!$K$2:$K$100)*(H3<=RESUMO!$L$2:$L$100), 0)), "R$ ", "")) ))))} -> 21.1 | K3: 0 | L3: =S3/H3 -> 0.0535712 | M3: 199.9 | N3: 0.16 | O3: {=IF(M3<12.5, 0, IF(M3<29, 6.25, IF(M3<50, 6.5, IF(M3<79, 6.75, VALUE(SUBSTITUTE( INDEX(RESUMO!$J$2:$J$100, MATCH(1, (D3>=RESUMO!$H$2:$H$100)*(D3<=RESUMO!$I$2:$I$100)*(M3>=RESUMO!$K$2:$K$100)*(M3<=RESUMO!$L$2:$L$100), 0)), "R$ ", "")) ))))} -> 21.1 | P3: 0 | Q3: =U3/M3 -> 0.055455728 | R3: =(H3-(H3*I3)-J3-(C3*E3)+K3) -> 140.5546 | S3: =R3-(C3-F3) -> 10.0446 | T3: =(M3-(M3*N3)-O3-(C3*E3)+P3) -> 141.5956 | U3: =T3-(C3-F3) -> 11.0856
A4: BRITANIA | B4: BRITANIA-JUI1000-127V | C4: 328.42 | D4: 9 | E4: 0.04 | F4: 0 | G4: 2 | H4: 403 | I4: 0.11 | J4: {=IF(H4<12.5, H4/2, IF(H4<29, 6.25, IF(H4<50, 6.5, IF(H4<79, 6.75, VALUE(SUBSTITUTE( INDEX(RESUMO!$J$2:$J$100, MATCH(1, (D4>=RESUMO!$H$2:$H$100)*(D4<=RESUMO!$I$2:$I$100)*(H4>=RESUMO!$K$2:$K$100)*(H4<=RESUMO!$L$2:$L$100), 0)), "R$ ", "")) ))))} -> 44.45 | K4: 19.2 | L4: =S4/H4 -> -0.020190571 | M4: 449.9 | N4: 0.16 | O4: {=IF(M4<12.5, 0, IF(M4<29, 6.25, IF(M4<50, 6.5, IF(M4<79, 6.75, VALUE(SUBSTITUTE( INDEX(RESUMO!$J$2:$J$100, MATCH(1, (D4>=RESUMO!$H$2:$H$100)*(D4<=RESUMO!$I$2:$I$100)*(M4>=RESUMO!$K$2:$K$100)*(M4<=RESUMO!$L$2:$L$100), 0)), "R$ ", "")) ))))} -> 44.45 | P4: 26.99 | Q4: =U4/M4 -> 0.042007557 | R4: =(H4-(H4*I4)-J4-(C4*E4)+K4) -> 320.2832 | S4: =R4-(C4-F4) -> -8.1368 | T4: =(M4-(M4*N4)-O4-(C4*E4)+P4) -> 347.3192 | U4: =T4-(C4-F4) -> 18.8992
A5: PHILCO | B5: PHILCO-PFE36S-220V | C5: 763.58 | D5: 13 | E5: 0.04 | F5: 0 | G5: 2 | H5: 1024.9 | I5: 0.11 | J5: {=IF(H5<12.5, H5/2, IF(H5<29, 6.25, IF(H5<50, 6.5, IF(H5<79, 6.75, VALUE(SUBSTITUTE( INDEX(RESUMO!$J$2:$J$100, MATCH(1, (D5>=RESUMO!$H$2:$H$100)*(D5<=RESUMO!$I$2:$I$100)*(H5>=RESUMO!$K$2:$K$100)*(H5<=RESUMO!$L$2:$L$100), 0)), "R$ ", "")) ))))} -> 65.95 | K5: 0 | L5: =S5/H5 -> 0.050822324 | M5: 1089.9 | N5: 0.16 | O5: {=IF(M5<12.5, 0, IF(M5<29, 6.25, IF(M5<50, 6.5, IF(M5<79, 6.75, VALUE(SUBSTITUTE( INDEX(RESUMO!$J$2:$J$100, MATCH(1, (D5>=RESUMO!$H$2:$H$100)*(D5<=RESUMO!$I$2:$I$100)*(M5>=RESUMO!$K$2:$K$100)*(M5<=RESUMO!$L$2:$L$100), 0)), "R$ ", "")) ))))} -> 65.95 | P5: 0 | Q5: =U5/M5 -> 0.050869621 | R5: =(H5-(H5*I5)-J5-(C5*E5)+K5) -> 815.6678 | S5: =R5-(C5-F5) -> 52.0878 | T5: =(M5-(M5*N5)-O5-(C5*E5)+P5) -> 819.0228 | U5: =T5-(C5-F5) -> 55.4428
A6: PHILCO | B6: PHILCO-NANO-CERAN-T-220V | C6: 124.4 | D6: 2 | E6: 0.04 | F6: 0 | G6: 2 | H6: 179.9 | I6: 0.11 | J6: {=IF(H6<12.5, H6/2, IF(H6<29, 6.25, IF(H6<50, 6.5, IF(H6<79, 6.75, VALUE(SUBSTITUTE( INDEX(RESUMO!$J$2:$J$100, MATCH(1, (D6>=RESUMO!$H$2:$H$100)*(D6<=RESUMO!$I$2:$I$100)*(H6>=RESUMO!$K$2:$K$100)*(H6<=RESUMO!$L$2:$L$100), 0)), "R$ ", "")) ))))} -> 21.1 | K6: 0 | L6: =S6/H6 -> 0.053557532 | M6: 191.5 | N6: 0.16 | O6: {=IF(M6<12.5, 0, IF(M6<29, 6.25, IF(M6<50, 6.5, IF(M6<79, 6.75, VALUE(SUBSTITUTE( INDEX(RESUMO!$J$2:$J$100, MATCH(1, (D6>=RESUMO!$H$2:$H$100)*(D6<=RESUMO!$I$2:$I$100)*(M6>=RESUMO!$K$2:$K$100)*(M6<=RESUMO!$L$2:$L$100), 0)), "R$ ", "")) ))))} -> 21.1 | P6: 0 | Q6: =U6/M6 -> 0.054224543 | R6: =(H6-(H6*I6)-J6-(C6*E6)+K6) -> 134.035 | S6: =R6-(C6-F6) -> 9.635 | T6: =(M6-(M6*N6)-O6-(C6*E6)+P6) -> 134.784 | U6: =T6-(C6-F6) -> 10.384
A7: PHILCO | B7: PHILCO-PTV32M9GACGB-127V | C7: 883.54 | D7: 9 | E7: 0.04 | F7: 40.41 | G7: 2 | H7: 995 | I7: 0.11 | J7: {=IF(H7<12.5, H7/2, IF(H7<29, 6.25, IF(H7<50, 6.5, IF(H7<79, 6.75, VALUE(SUBSTITUTE( INDEX(RESUMO!$J$2:$J$100, MATCH(1, (D7>=RESUMO!$H$2:$H$100)*(D7<=RESUMO!$I$2:$I$100)*(H7>=RESUMO!$K$2:$K$100)*(H7<=RESUMO!$L$2:$L$100), 0)), "R$ ", "")) ))))} -> 44.45 | K7: 0 | L7: =S7/H7 -> -0.037559397 | M7: 1099 | N7: 0.16 | O7: {=IF(M7<12.5, 0, IF(M7<29, 6.25, IF(M7<50, 6.5, IF(M7<79, 6.75, VALUE(SUBSTITUTE( INDEX(RESUMO!$J$2:$J$100, MATCH(1, (D7>=RESUMO!$H$2:$H$100)*(D7<=RESUMO!$I$2:$I$100)*(M7>=RESUMO!$K$2:$K$100)*(M7<=RESUMO!$L$2:$L$100), 0)), "R$ ", "")) ))))} -> 44.45 | P7: 0 | Q7: =U7/M7 -> 0.00021692448 | R7: =(H7-(H7*I7)-J7-(C7*E7)+K7) -> 805.7584 | S7: =R7-(C7-F7) -> -37.3716 | T7: =(M7-(M7*N7)-O7-(C7*E7)+P7) -> 843.3684 | U7: =T7-(C7-F7) -> 0.2384
A8: BRITANIA | B8: BRITANIA-BFE25P-127V | C8: 363.46 | D8: 13 | E8: 0.04 | F8: 0 | G8: 2 | H8: 449.9 | I8: 0.11 | J8: {=IF(H8<12.5, H8/2, IF(H8<29, 6.25, IF(H8<50, 6.5, IF(H8<79, 6.75, VALUE(SUBSTITUTE( INDEX(RESUMO!$J$2:$J$100, MATCH(1, (D8>=RESUMO!$H$2:$H$100)*(D8<=RESUMO!$I$2:$I$100)*(H8>=RESUMO!$K$2:$K$100)*(H8<=RESUMO!$L$2:$L$100), 0)), "R$ ", "")) ))))} -> 65.95 | K8: 0 | L8: =S8/H8 -> -0.096771283 | M8: 565 | N8: 0.16 | O8: {=IF(M8<12.5, 0, IF(M8<29, 6.25, IF(M8<50, 6.5, IF(M8<79, 6.75, VALUE(SUBSTITUTE( INDEX(RESUMO!$J$2:$J$100, MATCH(1, (D8>=RESUMO!$H$2:$H$100)*(D8<=RESUMO!$I$2:$I$100)*(M8>=RESUMO!$K$2:$K$100)*(M8<=RESUMO!$L$2:$L$100), 0)), "R$ ", "")) ))))} -> 65.95 | P8: 0 | Q8: =U8/M8 -> 0.054250619 | R8: =(H8-(H8*I8)-J8-(C8*E8)+K8) -> 319.9226 | S8: =R8-(C8-F8) -> -43.5374 | T8: =(M8-(M8*N8)-O8-(C8*E8)+P8) -> 394.1116 | U8: =T8-(C8-F8) -> 30.6516
A9: BRITANIA | B9: BRITANIA-BFE25P-220V | C9: 363.46 | D9: 13 | E9: 0.04 | F9: 0 | G9: 2 | H9: 499 | I9: 0.11 | J9: {=IF(H9<12.5, H9/2, IF(H9<29, 6.25, IF(H9<50, 6.5, IF(H9<79, 6.75, VALUE(SUBSTITUTE( INDEX(RESUMO!$J$2:$J$100, MATCH(1, (D9>=RESUMO!$H$2:$H$100)*(D9<=RESUMO!$I$2:$I$100)*(H9>=RESUMO!$K$2:$K$100)*(H9<=RESUMO!$L$2:$L$100), 0)), "R$ ", "")) ))))} -> 65.95 | K9: 0 | L9: =S9/H9 -> 0.0003238477 | M9: 566 | N9: 0.16 | O9: {=IF(M9<12.5, 0, IF(M9<29, 6.25, IF(M9<50, 6.5, IF(M9<79, 6.75, VALUE(SUBSTITUTE( INDEX(RESUMO!$J$2:$J$100, MATCH(1, (D9>=RESUMO!$H$2:$H$100)*(D9<=RESUMO!$I$2:$I$100)*(M9>=RESUMO!$K$2:$K$100)*(M9<=RESUMO!$L$2:$L$100), 0)), "R$ ", "")) ))))} -> 65.95 | P9: 0 | Q9: =U9/M9 -> 0.055638869 | R9: =(H9-(H9*I9)-J9-(C9*E9)+K9) -> 363.6216 | S9: =R9-(C9-F9) -> 0.1616 | T9: =(M9-(M9*N9)-O9-(C9*E9)+P9) -> 394.9516 | U9: =T9-(C9-F9) -> 31.4916
A10: PHILCO | B10: PHILCO-PTE03-BIV | C10: 86.88 | D10: 0.3 | E10: 0.04 | F10: 0 | G10: 2 | H10: 130.5 | I10: 0.12 | J10: {=IF(H10<12.5, H10/2, IF(H10<29, 6.25, IF(H10<50, 6.5, IF(H10<79, 6.75, VALUE(SUBSTITUTE( INDEX(RESUMO!$J$2:$J$100, MATCH(1, (D10>=RESUMO!$H$2:$H$100)*(D10<=RESUMO!$I$2:$I$100)*(H10>=RESUMO!$K$2:$K$100)*(H10<=RESUMO!$L$2:$L$100), 0)), "R$ ", "")) ))))} -> 15.96 | K10: 0 | L10: =S10/H10 -> 0.065324138 | M10: 139.5 | N10: 0.17 | O10: {=IF(M10<12.5, 0, IF(M10<29, 6.25, IF(M10<50, 6.5, IF(M10<79, 6.75, VALUE(SUBSTITUTE( INDEX(RESUMO!$J$2:$J$100, MATCH(1, (D10>=RESUMO!$H$2:$H$100)*(D10<=RESUMO!$I$2:$I$100)*(M10>=RESUMO!$K$2:$K$100)*(M10<=RESUMO!$L$2:$L$100), 0)), "R$ ", "")) ))))} -> 15.96 | P10: 0 | Q10: =U10/M10 -> 0.067883871 | R10: =(H10-(H10*I10)-J10-(C10*E10)+K10) -> 95.4048 | S10: =R10-(C10-F10) -> 8.5248 | T10: =(M10-(M10*N10)-O10-(C10*E10)+P10) -> 96.3498 | U10: =T10-(C10-F10) -> 9.4698
A11: PHILCO | B11: PHILCO-PMB37EB-127V | C11: 1167.99 | D11: 23 | E11: 0.04 | F11: 0 | G11: 2 | H11: 1549.9 | I11: 0.11 | J11: {=IF(H11<12.5, H11/2, IF(H11<29, 6.25, IF(H11<50, 6.5, IF(H11<79, 6.75, VALUE(SUBSTITUTE( INDEX(RESUMO!$J$2:$J$100, MATCH(1, (D11>=RESUMO!$H$2:$H$100)*(D11<=RESUMO!$I$2:$I$100)*(H11>=RESUMO!$K$2:$K$100)*(H11<=RESUMO!$L$2:$L$100), 0)), "R$ ", "")) ))))} -> 85.95 | K11: 0 | L11: =S11/H11 -> 0.050810633 | M11: 1759.12 | N11: 0.16 | O11: {=IF(M11<12.5, 0, IF(M11<29, 6.25, IF(M11<50, 6.5, IF(M11<79, 6.75, VALUE(SUBSTITUTE( INDEX(RESUMO!$J$2:$J$100, MATCH(1, (D11>=RESUMO!$H$2:$H$100)*(D11<=RESUMO!$I$2:$I$100)*(M11>=RESUMO!$K$2:$K$100)*(M11<=RESUMO!$L$2:$L$100), 0)), "R$ ", "")) ))))} -> 85.95 | P11: 0 | Q11: =U11/M11 -> 0.10061917 | R11: =(H11-(H11*I11)-J11-(C11*E11)+K11) -> 1246.7414 | S11: =R11-(C11-F11) -> 78.7514 | T11: =(M11-(M11*N11)-O11-(C11*E11)+P11) -> 1344.9912 | U11: =T11-(C11-F11) -> 177.0012
A12: PHILCO | B12: PHILCO-PMO23E-220V | C12: 459.3 | D12: 13 | E12: 0.04 | F12: 0 | G12: 2 | H12: 549 | I12: 0.11 | J12: {=IF(H12<12.5, H12/2, IF(H12<29, 6.25, IF(H12<50, 6.5, IF(H12<79, 6.75, VALUE(SUBSTITUTE( INDEX(RESUMO!$J$2:$J$100, MATCH(1, (D12>=RESUMO!$H$2:$H$100)*(D12<=RESUMO!$I$2:$I$100)*(H12>=RESUMO!$K$2:$K$100)*(H12<=RESUMO!$L$2:$L$100), 0)), "R$ ", "")) ))))} -> 65.95 | K12: 0 | L12: =S12/H12 -> -0.10020401 | M12: 689 | N12: 0.16 | O12: {=IF(M12<12.5, 0, IF(M12<29, 6.25, IF(M12<50, 6.5, IF(M12<79, 6.75, VALUE(SUBSTITUTE( INDEX(RESUMO!$J$2:$J$100, MATCH(1, (D12>=RESUMO!$H$2:$H$100)*(D12<=RESUMO!$I$2:$I$100)*(M12>=RESUMO!$K$2:$K$100)*(M12<=RESUMO!$L$2:$L$100), 0)), "R$ ", "")) ))))} -> 65.95 | P12: 0 | Q12: =U12/M12 -> 0.050998549 | R12: =(H12-(H12*I12)-J12-(C12*E12)+K12) -> 404.288 | S12: =R12-(C12-F12) -> -55.012 | T12: =(M12-(M12*N12)-O12-(C12*E12)+P12) -> 494.438 | U12: =T12-(C12-F12) -> 35.138
A13: PHILCO | B13: PHILCO-PMO28BB-127V | C13: 487.97 | D13: 13 | E13: 0.04 | F13: 0 | G13: 2 | H13: 685 | I13: 0.11 | J13: {=IF(H13<12.5, H13/2, IF(H13<29, 6.25, IF(H13<50, 6.5, IF(H13<79, 6.75, VALUE(SUBSTITUTE( INDEX(RESUMO!$J$2:$J$100, MATCH(1, (D13>=RESUMO!$H$2:$H$100)*(D13<=RESUMO!$I$2:$I$100)*(H13>=RESUMO!$K$2:$K$100)*(H13<=RESUMO!$L$2:$L$100), 0)), "R$ ", "")) ))))} -> 65.95 | K13: 0 | L13: =S13/H13 -> 0.052863066 | M13: 749 | N13: 0.16 | O13: {=IF(M13<12.5, 0, IF(M13<29, 6.25, IF(M13<50, 6.5, IF(M13<79, 6.75, VALUE(SUBSTITUTE( INDEX(RESUMO!$J$2:$J$100, MATCH(1, (D13>=RESUMO!$H$2:$H$100)*(D13<=RESUMO!$I$2:$I$100)*(M13>=RESUMO!$K$2:$K$100)*(M13<=RESUMO!$L$2:$L$100), 0)), "R$ ", "")) ))))} -> 65.95 | P13: 0 | Q13: =U13/M13 -> 0.074394126 | R13: =(H13-(H13*I13)-J13-(C13*E13)+K13) -> 524.1812 | S13: =R13-(C13-F13) -> 36.2112 | T13: =(M13-(M13*N13)-O13-(C13*E13)+P13) -> 543.6912 | U13: =T13-(C13-F13) -> 55.7212
... A25: PHILCO | B25: PHILCO-PTV100A5DGSPB-BIV | C25: 14845.96 | D25: 30 | E25: 0.04 | F25: 630.27 | G25: 0 | H25: 17690.2 | I25: 0.11 | J25: {=IF(H25<12.5, H25/2, IF(H25<29, 6.25, IF(H25<50, 6.5, IF(H25<79, 6.75, VALUE(SUBSTITUTE( INDEX(RESUMO!$J$2:$J$100, MATCH(1, (D25>=RESUMO!$H$2:$H$100)*(D25<=RESUMO!$I$2:$I$100)*(H25>=RESUMO!$K$2:$K$100)*(H25<=RESUMO!$L$2:$L$100), 0)), "R$ ", "")) ))))} -> 98.95 | K25: 229.98 | L25: =S25/H25 -> 0.060246894 | M25: 19133.06 | N25: 0.16 | O25: {=IF(M25<12.5, 0, IF(M25<29, 6.25, IF(M25<50, 6.5, IF(M25<79, 6.75, VALUE(SUBSTITUTE( INDEX(RESUMO!$J$2:$J$100, MATCH(1, (D25>=RESUMO!$H$2:$H$100)*(D25<=RESUMO!$I$2:$I$100)*(M25>=RESUMO!$K$2:$K$100)*(M25<=RESUMO!$L$2:$L$100), 0)), "R$ ", "")) ))))} -> 98.95 | P25: 230.69 | Q25: =U25/M25 -> 0.072857243 | R25: =(H25-(H25*I25)-J25-(C25*E25)+K25) -> 15281.47 | S25: =R25-(C25-F25) -> 1065.7796 | T25: =(M25-(M25*N25)-O25-(C25*E25)+P25) -> 15609.672 | U25: =T25-(C25-F25) -> 1393.982
A26: BRITANIA | B26: BRITANIA-BTV43VA4REGB-BIV | C26: 1238.87 | D26: 13 | E26: 0.04 | F26: 0 | G26: 0 | H26: 1661.55 | I26: 0.11 | K26: 0 | L26: =S26/H26 -> #VALUE! | M26: 1781.25 | N26: 0.16 | O26: {=IF(M26<12.5, 0, IF(M26<29, 6.25, IF(M26<50, 6.5, IF(M26<79, 6.75, VALUE(SUBSTITUTE( INDEX(RESUMO!$J$2:$J$100, MATCH(1, (D26>=RESUMO!$H$2:$H$100)*(D26<=RESUMO!$I$2:$I$100)*(M26>=RESUMO!$K$2:$K$100)*(M26<=RESUMO!$L$2:$L$100), 0)), "R$ ", "")) ))))} -> 65.95 | P26: 0 | Q26: =U26/M26 -> 0.079649235 | R26: =(H26-(H26*I26)-J26-(C26*E26)+K26) -> #VALUE! | S26: =R26-(C26-F26) -> #VALUE! | T26: =(M26-(M26*N26)-O26-(C26*E26)+P26) -> 1380.7452 | U26: =T26-(C26-F26) -> 141.8752
A27: BRITANIA | B27: BRITANIA-BTV50VA4REGB-BIV | C27: 1771.27 | D27: 23 | E27: 0.04 | F27: 0 | G27: 0 | H27: 2067.3 | I27: 0.11 | J27: {=IF(H27<12.5, H27/2, IF(H27<29, 6.25, IF(H27<50, 6.5, IF(H27<79, 6.75, VALUE(SUBSTITUTE( INDEX(RESUMO!$J$2:$J$100, MATCH(1, (D27>=RESUMO!$H$2:$H$100)*(D27<=RESUMO!$I$2:$I$100)*(H27>=RESUMO!$K$2:$K$100)*(H27<=RESUMO!$L$2:$L$100), 0)), "R$ ", "")) ))))} -> 85.95 | K27: 0 | L27: =S27/H27 -> -0.042651671 | M27: 2493.14 | N27: 0.16 | O27: {=IF(M27<12.5, 0, IF(M27<29, 6.25, IF(M27<50, 6.5, IF(M27<79, 6.75, VALUE(SUBSTITUTE( INDEX(RESUMO!$J$2:$J$100, MATCH(1, (D27>=RESUMO!$H$2:$H$100)*(D27<=RESUMO!$I$2:$I$100)*(M27>=RESUMO!$K$2:$K$100)*(M27<=RESUMO!$L$2:$L$100), 0)), "R$ ", "")) ))))} -> 85.95 | P27: 0 | Q27: =U27/M27 -> 0.066649607 | R27: =(H27-(H27*I27)-J27-(C27*E27)+K27) -> 1683.0962 | S27: =R27-(C27-F27) -> -88.1738 | T27: =(M27-(M27*N27)-O27-(C27*E27)+P27) -> 1937.4368 | U27: =T27-(C27-F27) -> 166.1668
A28: PHILCO | B28: PHILCO-PTV42G6FR2CPF-42 | C28: 1238.87 | D28: 13 | E28: 0.04 | F28: 0 | G28: 0 | H28: 1443.91 | I28: 0.11 | J28: {=IF(H28<12.5, H28/2, IF(H28<29, 6.25, IF(H28<50, 6.5, IF(H28<79, 6.75, VALUE(SUBSTITUTE( INDEX(RESUMO!$J$2:$J$100, MATCH(1, (D28>=RESUMO!$H$2:$H$100)*(D28<=RESUMO!$I$2:$I$100)*(H28>=RESUMO!$K$2:$K$100)*(H28<=RESUMO!$L$2:$L$100), 0)), "R$ ", "")) ))))} -> 65.95 | K28: 0 | L28: =S28/H28 -> -0.047991149 | M28: 1642.5 | N28: 0.16 | O28: {=IF(M28<12.5, 0, IF(M28<29, 6.25, IF(M28<50, 6.5, IF(M28<79, 6.75, VALUE(SUBSTITUTE( INDEX(RESUMO!$J$2:$J$100, MATCH(1, (D28>=RESUMO!$H$2:$H$100)*(D28<=RESUMO!$I$2:$I$100)*(M28>=RESUMO!$K$2:$K$100)*(M28<=RESUMO!$L$2:$L$100), 0)), "R$ ", "")) ))))} -> 65.95 | P28: 0 | Q28: =U28/M28 -> 0.015418691 | R28: =(H28-(H28*I28)-J28-(C28*E28)+K28) -> 1169.5751 | S28: =R28-(C28-F28) -> -69.2949 | T28: =(M28-(M28*N28)-O28-(C28*E28)+P28) -> 1264.1952 | U28: =T28-(C28-F28) -> 25.3252
A29: PHILCO | B29: PHILCO-PMO33EB-127V | C29: 608.23 | D29: 17 | E29: 0.04 | F29: 0 | G29: 2 | H29: 845.06 | I29: 0.11 | J29: {=IF(H29<12.5, H29/2, IF(H29<29, 6.25, IF(H29<50, 6.5, IF(H29<79, 6.75, VALUE(SUBSTITUTE( INDEX(RESUMO!$J$2:$J$100, MATCH(1, (D29>=RESUMO!$H$2:$H$100)*(D29<=RESUMO!$I$2:$I$100)*(H29>=RESUMO!$K$2:$K$100)*(H29<=RESUMO!$L$2:$L$100), 0)), "R$ ", "")) ))))} -> 73.45 | K29: 0 | L29: =S29/H29 -> 0.054545476 | M29: 899.9 | N29: 0.16 | O29: {=IF(M29<12.5, 0, IF(M29<29, 6.25, IF(M29<50, 6.5, IF(M29<79, 6.75, VALUE(SUBSTITUTE( INDEX(RESUMO!$J$2:$J$100, MATCH(1, (D29>=RESUMO!$H$2:$H$100)*(D29<=RESUMO!$I$2:$I$100)*(M29>=RESUMO!$K$2:$K$100)*(M29<=RESUMO!$L$2:$L$100), 0)), "R$ ", "")) ))))} -> 73.45 | P29: 0 | Q29: =U29/M29 -> 0.055458162 | R29: =(H29-(H29*I29)-J29-(C29*E29)+K29) -> 654.3242 | S29: =R29-(C29-F29) -> 46.0942 | T29: =(M29-(M29*N29)-O29-(C29*E29)+P29) -> 658.1368 | U29: =T29-(C29-F29) -> 49.9068
A30: PHILCO | B30: PHILCO-PMO33IP-127V | C30: 613.74 | D30: 17 | E30: 0.04 | F30: 0 | G30: 2 | H30: 799.9 | I30: 0.11 | J30: {=IF(H30<12.5, H30/2, IF(H30<29, 6.25, IF(H30<50, 6.5, IF(H30<79, 6.75, VALUE(SUBSTITUTE( INDEX(RESUMO!$J$2:$J$100, MATCH(1, (D30>=RESUMO!$H$2:$H$100)*(D30<=RESUMO!$I$2:$I$100)*(H30>=RESUMO!$K$2:$K$100)*(H30<=RESUMO!$L$2:$L$100), 0)), "R$ ", "")) ))))} -> 73.45 | K30: 0 | L30: =S30/H30 -> 0.00021427678 | M30: 849 | N30: 0.16 | O30: {=IF(M30<12.5, 0, IF(M30<29, 6.25, IF(M30<50, 6.5, IF(M30<79, 6.75, VALUE(SUBSTITUTE( INDEX(RESUMO!$J$2:$J$100, MATCH(1, (D30>=RESUMO!$H$2:$H$100)*(D30<=RESUMO!$I$2:$I$100)*(M30>=RESUMO!$K$2:$K$100)*(M30<=RESUMO!$L$2:$L$100), 0)), "R$ ", "")) ))))} -> 73.45 | P30: 0 | Q30: =U30/M30 -> 0.0016730271 | R30: =(H30-(H30*I30)-J30-(C30*E30)+K30) -> 613.9114 | S30: =R30-(C30-F30) -> 0.1714 | T30: =(M30-(M30*N30)-O30-(C30*E30)+P30) -> 615.1604 | U30: =T30-(C30-F30) -> 1.4204
A31: PHILCO | B31: PHILCO-PTV40M9GACGB-BIV | C31: 1197.91 | D31: 13 | E31: 0.04 | F31: 0 | G31: 0 | H31: 1399 | I31: 0.11 | J31: {=IF(H31<12.5, H31/2, IF(H31<29, 6.25, IF(H31<50, 6.5, IF(H31<79, 6.75, VALUE(SUBSTITUTE( INDEX(RESUMO!$J$2:$J$100, MATCH(1, (D31>=RESUMO!$H$2:$H$100)*(D31<=RESUMO!$I$2:$I$100)*(H31>=RESUMO!$K$2:$K$100)*(H31<=RESUMO!$L$2:$L$100), 0)), "R$ ", "")) ))))} -> 65.95 | K31: 0 | L31: =S31/H31 -> -0.047652895 | M31: 1614.15 | N31: 0.16 | O31: {=IF(M31<12.5, 0, IF(M31<29, 6.25, IF(M31<50, 6.5, IF(M31<79, 6.75, VALUE(SUBSTITUTE( INDEX(RESUMO!$J$2:$J$100, MATCH(1, (D31>=RESUMO!$H$2:$H$100)*(D31<=RESUMO!$I$2:$I$100)*(M31>=RESUMO!$K$2:$K$100)*(M31<=RESUMO!$L$2:$L$100), 0)), "R$ ", "")) ))))} -> 65.95 | P31: 0 | Q31: =U31/M31 -> 0.027326828 | R31: =(H31-(H31*I31)-J31-(C31*E31)+K31) -> 1131.2436 | S31: =R31-(C31-F31) -> -66.6664 | T31: =(M31-(M31*N31)-O31-(C31*E31)+P31) -> 1242.0196 | U31: =T31-(C31-F31) -> 44.1096
A32: PHILCO | B32: PHILCO-PMO38B-220V | C32: 549.54 | D32: 17 | E32: 0.04 | F32: 0 | G32: 2 | H32: 729 | I32: 0.11 | J32: {=IF(H32<12.5, H32/2, IF(H32<29, 6.25, IF(H32<50, 6.5, IF(H32<79, 6.75, VALUE(SUBSTITUTE( INDEX(RESUMO!$J$2:$J$100, MATCH(1, (D32>=RESUMO!$H$2:$H$100)*(D32<=RESUMO!$I$2:$I$100)*(H32>=RESUMO!$K$2:$K$100)*(H32<=RESUMO!$L$2:$L$100), 0)), "R$ ", "")) ))))} -> 73.45 | K32: 0 | L32: =S32/H32 -> 0.0052652949 | M32: 775 | N32: 0.16 | O32: {=IF(M32<12.5, 0, IF(M32<29, 6.25, IF(M32<50, 6.5, IF(M32<79, 6.75, VALUE(SUBSTITUTE( INDEX(RESUMO!$J$2:$J$100, MATCH(1, (D32>=RESUMO!$H$2:$H$100)*(D32<=RESUMO!$I$2:$I$100)*(M32>=RESUMO!$K$2:$K$100)*(M32<=RESUMO!$L$2:$L$100), 0)), "R$ ", "")) ))))} -> 73.45 | P32: 0 | Q32: =U32/M32 -> 0.0077785806 | R32: =(H32-(H32*I32)-J32-(C32*E32)+K32) -> 553.3784 | S32: =R32-(C32-F32) -> 3.8384 | T32: =(M32-(M32*N32)-O32-(C32*E32)+P32) -> 555.5684 | U32: =T32-(C32-F32) -> 6.0284
A33: PHILCO | B33: PHILCO-PMO23B-220V | C33: 439.02 | D33: 13 | E33: 0.04 | F33: 0 | G33: 2 | H33: 623.5 | I33: 0.11 | J33: {=IF(H33<12.5, H33/2, IF(H33<29, 6.25, IF(H33<50, 6.5, IF(H33<79, 6.75, VALUE(SUBSTITUTE( INDEX(RESUMO!$J$2:$J$100, MATCH(1, (D33>=RESUMO!$H$2:$H$100)*(D33<=RESUMO!$I$2:$I$100)*(H33>=RESUMO!$K$2:$K$100)*(H33<=RESUMO!$L$2:$L$100), 0)), "R$ ", "")) ))))} -> 65.95 | K33: 0 | L33: =S33/H33 -> 0.051939374 | M33: 665 | N33: 0.16 | O33: {=IF(M33<12.5, 0, IF(M33<29, 6.25, IF(M33<50, 6.5, IF(M33<79, 6.75, VALUE(SUBSTITUTE( INDEX(RESUMO!$J$2:$J$100, MATCH(1, (D33>=RESUMO!$H$2:$H$100)*(D33<=RESUMO!$I$2:$I$100)*(M33>=RESUMO!$K$2:$K$100)*(M33<=RESUMO!$L$2:$L$100), 0)), "R$ ", "")) ))))} -> 65.95 | P33: 0 | Q33: =U33/M33 -> 0.054239398 | R33: =(H33-(H33*I33)-J33-(C33*E33)+K33) -> 471.4042 | S33: =R33-(C33-F33) -> 32.3842 | T33: =(M33-(M33*N33)-O33-(C33*E33)+P33) -> 475.0892 | U33: =T33-(C33-F33) -> 36.0692
A34: BRITANIA | B34: BRITANIA-BMO23-220V | C34: 439.02 | D34: 17 | E34: 0.04 | F34: 0 | G34: 2 | H34: 549.9 | I34: 0.11 | J34: {=IF(H34<12.5, H34/2, IF(H34<29, 6.25, IF(H34<50, 6.5, IF(H34<79, 6.75, VALUE(SUBSTITUTE( INDEX(RESUMO!$J$2:$J$100, MATCH(1, (D34>=RESUMO!$H$2:$H$100)*(D34<=RESUMO!$I$2:$I$100)*(H34>=RESUMO!$K$2:$K$100)*(H34<=RESUMO!$L$2:$L$100), 0)), "R$ ", "")) ))))} -> 73.45 | K34: 0 | L34: =S34/H34 -> -0.073867612 | M34: 599 | N34: 0.16 | O34: {=IF(M34<12.5, 0, IF(M34<29, 6.25, IF(M34<50, 6.5, IF(M34<79, 6.75, VALUE(SUBSTITUTE( INDEX(RESUMO!$J$2:$J$100, MATCH(1, (D34>=RESUMO!$H$2:$H$100)*(D34<=RESUMO!$I$2:$I$100)*(M34>=RESUMO!$K$2:$K$100)*(M34<=RESUMO!$L$2:$L$100), 0)), "R$ ", "")) ))))} -> 73.45 | P34: 0 | Q34: =U34/M34 -> -0.044859432 | R34: =(H34-(H34*I34)-J34-(C34*E34)+K34) -> 398.4002 | S34: =R34-(C34-F34) -> -40.6198 | T34: =(M34-(M34*N34)-O34-(C34*E34)+P34) -> 412.1492 | U34: =T34-(C34-F34) -> -26.8708
A35: PHILCO | B35: PHILCO-PDR60P-220V | C35: 266.68 | D35: 70 | E35: 0.04 | F35: 0 | G35: 0 | H35: 483 | I35: 0.11 | J35: {=IF(H35<12.5, H35/2, IF(H35<29, 6.25, IF(H35<50, 6.5, IF(H35<79, 6.75, VALUE(SUBSTITUTE( INDEX(RESUMO!$J$2:$J$100, MATCH(1, (D35>=RESUMO!$H$2:$H$100)*(D35<=RESUMO!$I$2:$I$100)*(H35>=RESUMO!$K$2:$K$100)*(H35<=RESUMO!$L$2:$L$100), 0)), "R$ ", "")) ))))} -> 120.45 | K35: 0 | L35: =S35/H35 -> 0.066403313 | M35: 529 | N35: 0.16 | O35: {=IF(M35<12.5, 0, IF(M35<29, 6.25, IF(M35<50, 6.5, IF(M35<79, 6.75, VALUE(SUBSTITUTE( INDEX(RESUMO!$J$2:$J$100, MATCH(1, (D35>=RESUMO!$H$2:$H$100)*(D35<=RESUMO!$I$2:$I$100)*(M35>=RESUMO!$K$2:$K$100)*(M35<=RESUMO!$L$2:$L$100), 0)), "R$ ", "")) ))))} -> 120.45 | P35: 0 | Q35: =U35/M35 -> 0.088020416 | R35: =(H35-(H35*I35)-J35-(C35*E35)+K35) -> 298.7528 | S35: =R35-(C35-F35) -> 32.0728 | T35: =(M35-(M35*N35)-O35-(C35*E35)+P35) -> 313.2428 | U35: =T35-(C35-F35) -> 46.5628
A36: PHILCO | B36: PHILCO-PMG01PI-220V | C36: 822.61 | D36: 9 | E36: 0.04 | F36: 0 | G36: 2 | H36: 1015 | I36: 0.11 | J36: {=IF(H36<12.5, H36/2, IF(H36<29, 6.25, IF(H36<50, 6.5, IF(H36<79, 6.75, VALUE(SUBSTITUTE( INDEX(RESUMO!$J$2:$J$100, MATCH(1, (D36>=RESUMO!$H$2:$H$100)*(D36<=RESUMO!$I$2:$I$100)*(H36>=RESUMO!$K$2:$K$100)*(H36<=RESUMO!$L$2:$L$100), 0)), "R$ ", "")) ))))} -> 44.45 | K36: 0 | L36: =S36/H36 -> 0.0033355665 | M36: 1095 | N36: 0.17 | O36: {=IF(M36<12.5, 0, IF(M36<29, 6.25, IF(M36<50, 6.5, IF(M36<79, 6.75, VALUE(SUBSTITUTE( INDEX(RESUMO!$J$2:$J$100, MATCH(1, (D36>=RESUMO!$H$2:$H$100)*(D36<=RESUMO!$I$2:$I$100)*(M36>=RESUMO!$K$2:$K$100)*(M36<=RESUMO!$L$2:$L$100), 0)), "R$ ", "")) ))))} -> 44.45 | P36: 0 | Q36: =U36/M36 -> 0.0081147032 | R36: =(H36-(H36*I36)-J36-(C36*E36)+K36) -> 825.9956 | S36: =R36-(C36-F36) -> 3.3856 | T36: =(M36-(M36*N36)-O36-(C36*E36)+P36) -> 831.4956 | U36: =T36-(C36-F36) -> 8.8856
A37: PHILCO | B37: PHILCO-PCO60G-220V | C37: 591.67 | D37: 70 | E37: 0.04 | F37: 0 | G37: 0 | H37: 897.45 | I37: 0.11 | J37: {=IF(H37<12.5, H37/2, IF(H37<29, 6.25, IF(H37<50, 6.5, IF(H37<79, 6.75, VALUE(SUBSTITUTE( INDEX(RESUMO!$J$2:$J$100, MATCH(1, (D37>=RESUMO!$H$2:$H$100)*(D37<=RESUMO!$I$2:$I$100)*(H37>=RESUMO!$K$2:$K$100)*(H37<=RESUMO!$L$2:$L$100), 0)), "R$ ", "")) ))))} -> 120.45 | K37: 0 | L37: =S37/H37 -> 0.070136164 | M37: 1025 | N37: 0.16 | O37: {=IF(M37<12.5, 0, IF(M37<29, 6.25, IF(M37<50, 6.5, IF(M37<79, 6.75, VALUE(SUBSTITUTE( INDEX(RESUMO!$J$2:$J$100, MATCH(1, (D37>=RESUMO!$H$2:$H$100)*(D37<=RESUMO!$I$2:$I$100)*(M37>=RESUMO!$K$2:$K$100)*(M37<=RESUMO!$L$2:$L$100), 0)), "R$ ", "")) ))))} -> 120.45 | P37: 0 | Q37: =U37/M37 -> 0.12215922 | R37: =(H37-(H37*I37)-J37-(C37*E37)+K37) -> 654.6137 | S37: =R37-(C37-F37) -> 62.9437 | T37: =(M37-(M37*N37)-O37-(C37*E37)+P37) -> 716.8832 | U37: =T37-(C37-F37) -> 125.2132
A38: PHILCO | B38: PHILCO-PAD24DZ-BIV | C38: 1327.28 | D38: 40 | E38: 0.04 | F38: 0 | G38: 2 | H38: 1685 | I38: 0.115 | J38: {=IF(H38<12.5, H38/2, IF(H38<29, 6.25, IF(H38<50, 6.5, IF(H38<79, 6.75, VALUE(SUBSTITUTE( INDEX(RESUMO!$J$2:$J$100, MATCH(1, (D38>=RESUMO!$H$2:$H$100)*(D38<=RESUMO!$I$2:$I$100)*(H38>=RESUMO!$K$2:$K$100)*(H38<=RESUMO!$L$2:$L$100), 0)), "R$ ", "")) ))))} -> 101.95 | K38: 0 | L38: =S38/H38 -> 0.0052841543 | M38: 1785 | N38: 0.165 | O38: {=IF(M38<12.5, 0, IF(M38<29, 6.25, IF(M38<50, 6.5, IF(M38<79, 6.75, VALUE(SUBSTITUTE( INDEX(RESUMO!$J$2:$J$100, MATCH(1, (D38>=RESUMO!$H$2:$H$100)*(D38<=RESUMO!$I$2:$I$100)*(M38>=RESUMO!$K$2:$K$100)*(M38<=RESUMO!$L$2:$L$100), 0)), "R$ ", "")) ))))} -> 101.95 | P38: 0 | Q38: =U38/M38 -> 0.0045679552 | R38: =(H38-(H38*I38)-J38-(C38*E38)+K38) -> 1336.1838 | S38: =R38-(C38-F38) -> 8.9038 | T38: =(M38-(M38*N38)-O38-(C38*E38)+P38) -> 1335.4338 | U38: =T38-(C38-F38) -> 8.1538
... A53: MONDIAL | B53: MONDIAL-FR-42-127V | C53: 298.9 | D53: 17 | E53: 0.04 | F53: 0 | G53: 2 | H53: 432 | I53: 0.11 | J53: {=IF(H53<12.5, H53/2, IF(H53<29, 6.25, IF(H53<50, 6.5, IF(H53<79, 6.75, VALUE(SUBSTITUTE( INDEX(RESUMO!$J$2:$J$100, MATCH(1, (D53>=RESUMO!$H$2:$H$100)*(D53<=RESUMO!$I$2:$I$100)*(H53>=RESUMO!$K$2:$K$100)*(H53<=RESUMO!$L$2:$L$100), 0)), "R$ ", "")) ))))} -> 73.45 | K53: 0 | L53: =S53/H53 -> 0.00040277778 | M53: 459 | N53: 0.16 | O53: {=IF(M53<12.5, 0, IF(M53<29, 6.25, IF(M53<50, 6.5, IF(M53<79, 6.75, VALUE(SUBSTITUTE( INDEX(RESUMO!$J$2:$J$100, MATCH(1, (D53>=RESUMO!$H$2:$H$100)*(D53<=RESUMO!$I$2:$I$100)*(M53>=RESUMO!$K$2:$K$100)*(M53<=RESUMO!$L$2:$L$100), 0)), "R$ ", "")) ))))} -> 73.45 | P53: 0 | Q53: =U53/M53 -> 0.0027320261 | R53: =(H53-(H53*I53)-J53-(C53*E53)+K53) -> 299.074 | S53: =R53-(C53-F53) -> 0.174 | T53: =(M53-(M53*N53)-O53-(C53*E53)+P53) -> 300.154 | U53: =T53-(C53-F53) -> 1.254
A54: MONDIAL | B54: MONDIAL-ES-14-127V | C54: 106.99 | D54: 1 | E54: 0.04 | F54: 0 | G54: 2 | H54: 145.4 | I54: 0.12 | J54: {=IF(H54<12.5, H54/2, IF(H54<29, 6.25, IF(H54<50, 6.5, IF(H54<79, 6.75, VALUE(SUBSTITUTE( INDEX(RESUMO!$J$2:$J$100, MATCH(1, (D54>=RESUMO!$H$2:$H$100)*(D54<=RESUMO!$I$2:$I$100)*(H54>=RESUMO!$K$2:$K$100)*(H54<=RESUMO!$L$2:$L$100), 0)), "R$ ", "")) ))))} -> 17.95 | K54: 1.86 | L54: =S54/H54 -> 0.0040742779 | O54: {=IF(M54<12.5, 0, IF(M54<29, 6.25, IF(M54<50, 6.5, IF(M54<79, 6.75, VALUE(SUBSTITUTE( INDEX(RESUMO!$J$2:$J$100, MATCH(1, (D54>=RESUMO!$H$2:$H$100)*(D54<=RESUMO!$I$2:$I$100)*(M54>=RESUMO!$K$2:$K$100)*(M54<=RESUMO!$L$2:$L$100), 0)), "R$ ", "")) ))))} -> 0 | Q54: =U54/M54 -> #DIV/0! | R54: =(H54-(H54*I54)-J54-(C54*E54)+K54) -> 107.5824 | S54: =R54-(C54-F54) -> 0.5924 | T54: =(M54-(M54*N54)-O54-(C54*E54)+P54) -> -4.2796 | U54: =T54-(C54-F54) -> -111.2696
A55: THUNDEROBOT | B55: THUNDEROBOT-MG301 | C55: 139.2 | D55: 0.3 | E55: 0.04 | F55: 0 | G55: 2 | H55: 165 | I55: 0.13 | J55: {=IF(H55<12.5, H55/2, IF(H55<29, 6.25, IF(H55<50, 6.5, IF(H55<79, 6.75, VALUE(SUBSTITUTE( INDEX(RESUMO!$J$2:$J$100, MATCH(1, (D55>=RESUMO!$H$2:$H$100)*(D55<=RESUMO!$I$2:$I$100)*(H55>=RESUMO!$K$2:$K$100)*(H55<=RESUMO!$L$2:$L$100), 0)), "R$ ", "")) ))))} -> 17.95 | K55: 0 | L55: =S55/H55 -> -0.1161697 | O55: {=IF(M55<12.5, 0, IF(M55<29, 6.25, IF(M55<50, 6.5, IF(M55<79, 6.75, VALUE(SUBSTITUTE( INDEX(RESUMO!$J$2:$J$100, MATCH(1, (D55>=RESUMO!$H$2:$H$100)*(D55<=RESUMO!$I$2:$I$100)*(M55>=RESUMO!$K$2:$K$100)*(M55<=RESUMO!$L$2:$L$100), 0)), "R$ ", "")) ))))} -> 0 | Q55: =U55/M55 -> #DIV/0! | R55: =(H55-(H55*I55)-J55-(C55*E55)+K55) -> 120.032 | S55: =R55-(C55-F55) -> -19.168 | T55: =(M55-(M55*N55)-O55-(C55*E55)+P55) -> -5.568 | U55: =T55-(C55-F55) -> -144.768
A56: THUNDEROBOT | B56: THUNDEROBOT-H3 | C56: 140.37 | D56: 2 | E56: 0.04 | F56: 0 | G56: 2 | H56: 129.9 | I56: 0.13 | J56: {=IF(H56<12.5, H56/2, IF(H56<29, 6.25, IF(H56<50, 6.5, IF(H56<79, 6.75, VALUE(SUBSTITUTE( INDEX(RESUMO!$J$2:$J$100, MATCH(1, (D56>=RESUMO!$H$2:$H$100)*(D56<=RESUMO!$I$2:$I$100)*(H56>=RESUMO!$K$2:$K$100)*(H56<=RESUMO!$L$2:$L$100), 0)), "R$ ", "")) ))))} -> 18.76 | K56: 0 | L56: =S56/H56 -> -0.39824326 | O56: {=IF(M56<12.5, 0, IF(M56<29, 6.25, IF(M56<50, 6.5, IF(M56<79, 6.75, VALUE(SUBSTITUTE( INDEX(RESUMO!$J$2:$J$100, MATCH(1, (D56>=RESUMO!$H$2:$H$100)*(D56<=RESUMO!$I$2:$I$100)*(M56>=RESUMO!$K$2:$K$100)*(M56<=RESUMO!$L$2:$L$100), 0)), "R$ ", "")) ))))} -> 0 | Q56: =U56/M56 -> #DIV/0! | R56: =(H56-(H56*I56)-J56-(C56*E56)+K56) -> 88.6382 | S56: =R56-(C56-F56) -> -51.7318 | T56: =(M56-(M56*N56)-O56-(C56*E56)+P56) -> -5.6148 | U56: =T56-(C56-F56) -> -145.9848
A57: THUNDEROBOT | B57: THUNDEROBOT-HG503 | C57: 204.75 | D57: 3 | E57: 0.04 | F57: 0 | G57: 2 | H57: 199.9 | I57: 0.13 | J57: {=IF(H57<12.5, H57/2, IF(H57<29, 6.25, IF(H57<50, 6.5, IF(H57<79, 6.75, VALUE(SUBSTITUTE( INDEX(RESUMO!$J$2:$J$100, MATCH(1, (D57>=RESUMO!$H$2:$H$100)*(D57<=RESUMO!$I$2:$I$100)*(H57>=RESUMO!$K$2:$K$100)*(H57<=RESUMO!$L$2:$L$100), 0)), "R$ ", "")) ))))} -> 22.45 | K57: 0 | L57: =S57/H57 -> -0.30753877 | O57: {=IF(M57<12.5, 0, IF(M57<29, 6.25, IF(M57<50, 6.5, IF(M57<79, 6.75, VALUE(SUBSTITUTE( INDEX(RESUMO!$J$2:$J$100, MATCH(1, (D57>=RESUMO!$H$2:$H$100)*(D57<=RESUMO!$I$2:$I$100)*(M57>=RESUMO!$K$2:$K$100)*(M57<=RESUMO!$L$2:$L$100), 0)), "R$ ", "")) ))))} -> 0 | Q57: =U57/M57 -> #DIV/0! | R57: =(H57-(H57*I57)-J57-(C57*E57)+K57) -> 143.273 | S57: =R57-(C57-F57) -> -61.477 | T57: =(M57-(M57*N57)-O57-(C57*E57)+P57) -> -8.19 | U57: =T57-(C57-F57) -> -212.94
A58: PHILCO | B58: PHILCO-PAS1450C-220V | C58: 119.67 | D58: 3 | E58: 0.04 | F58: 0 | G58: 2 | H58: 165 | I58: 0.11 | J58: {=IF(H58<12.5, H58/2, IF(H58<29, 6.25, IF(H58<50, 6.5, IF(H58<79, 6.75, VALUE(SUBSTITUTE( INDEX(RESUMO!$J$2:$J$100, MATCH(1, (D58>=RESUMO!$H$2:$H$100)*(D58<=RESUMO!$I$2:$I$100)*(H58>=RESUMO!$K$2:$K$100)*(H58<=RESUMO!$L$2:$L$100), 0)), "R$ ", "")) ))))} -> 22.45 | K58: 0 | L58: =S58/H58 -> -0.00034424242 | M58: 175 | N58: 0.16 | O58: {=IF(M58<12.5, 0, IF(M58<29, 6.25, IF(M58<50, 6.5, IF(M58<79, 6.75, VALUE(SUBSTITUTE( INDEX(RESUMO!$J$2:$J$100, MATCH(1, (D58>=RESUMO!$H$2:$H$100)*(D58<=RESUMO!$I$2:$I$100)*(M58>=RESUMO!$K$2:$K$100)*(M58<=RESUMO!$L$2:$L$100), 0)), "R$ ", "")) ))))} -> 22.45 | P58: 0 | Q58: =U58/M58 -> 0.00053257143 | R58: =(H58-(H58*I58)-J58-(C58*E58)+K58) -> 119.6132 | S58: =R58-(C58-F58) -> -0.0568 | T58: =(M58-(M58*N58)-O58-(C58*E58)+P58) -> 119.7632 | U58: =T58-(C58-F58) -> 0.0932
A59: BRITANIA | B59: BRITANIA-BAS1500V-127V | C59: 130.51 | D59: 3 | E59: 0.04 | F59: 0 | G59: 0 | H59: 191.4 | I59: 0.11 | J59: {=IF(H59<12.5, H59/2, IF(H59<29, 6.25, IF(H59<50, 6.5, IF(H59<79, 6.75, VALUE(SUBSTITUTE( INDEX(RESUMO!$J$2:$J$100, MATCH(1, (D59>=RESUMO!$H$2:$H$100)*(D59<=RESUMO!$I$2:$I$100)*(H59>=RESUMO!$K$2:$K$100)*(H59<=RESUMO!$L$2:$L$100), 0)), "R$ ", "")) ))))} -> 22.45 | K59: 0 | L59: =S59/H59 -> 0.063561129 | M59: 204.45 | N59: 0.16 | O59: {=IF(M59<12.5, 0, IF(M59<29, 6.25, IF(M59<50, 6.5, IF(M59<79, 6.75, VALUE(SUBSTITUTE( INDEX(RESUMO!$J$2:$J$100, MATCH(1, (D59>=RESUMO!$H$2:$H$100)*(D59<=RESUMO!$I$2:$I$100)*(M59>=RESUMO!$K$2:$K$100)*(M59<=RESUMO!$L$2:$L$100), 0)), "R$ ", "")) ))))} -> 24.95 | P59: 0 | Q59: =U59/M59 -> 0.054084617 | R59: =(H59-(H59*I59)-J59-(C59*E59)+K59) -> 142.6756 | S59: =R59-(C59-F59) -> 12.1656 | T59: =(M59-(M59*N59)-O59-(C59*E59)+P59) -> 141.5676 | U59: =T59-(C59-F59) -> 11.0576
A60: PHILCO | B60: PHILCO-PAS1600P-220V | C60: 135.64 | D60: 3 | E60: 0.04 | F60: 0 | G60: 2 | H60: 185 | I60: 0.11 | J60: {=IF(H60<12.5, H60/2, IF(H60<29, 6.25, IF(H60<50, 6.5, IF(H60<79, 6.75, VALUE(SUBSTITUTE( INDEX(RESUMO!$J$2:$J$100, MATCH(1, (D60>=RESUMO!$H$2:$H$100)*(D60<=RESUMO!$I$2:$I$100)*(H60>=RESUMO!$K$2:$K$100)*(H60<=RESUMO!$L$2:$L$100), 0)), "R$ ", "")) ))))} -> 22.45 | K60: 0 | L60: =S60/H60 -> 0.0061318919 | M60: 195 | N60: 0.16 | O60: {=IF(M60<12.5, 0, IF(M60<29, 6.25, IF(M60<50, 6.5, IF(M60<79, 6.75, VALUE(SUBSTITUTE( INDEX(RESUMO!$J$2:$J$100, MATCH(1, (D60>=RESUMO!$H$2:$H$100)*(D60<=RESUMO!$I$2:$I$100)*(M60>=RESUMO!$K$2:$K$100)*(M60<=RESUMO!$L$2:$L$100), 0)), "R$ ", "")) ))))} -> 22.45 | P60: 0 | Q60: =U60/M60 -> 0.0014584615 | R60: =(H60-(H60*I60)-J60-(C60*E60)+K60) -> 136.7744 | S60: =R60-(C60-F60) -> 1.1344 | T60: =(M60-(M60*N60)-O60-(C60*E60)+P60) -> 135.9244 | U60: =T60-(C60-F60) -> 0.2844
A61: PHILCO | B61: PHILCO-PAS1600P-127V | C61: 135.64 | D61: 3 | E61: 0.04 | F61: 0 | G61: 2 | H61: 185 | I61: 0.11 | J61: {=IF(H61<12.5, H61/2, IF(H61<29, 6.25, IF(H61<50, 6.5, IF(H61<79, 6.75, VALUE(SUBSTITUTE( INDEX(RESUMO!$J$2:$J$100, MATCH(1, (D61>=RESUMO!$H$2:$H$100)*(D61<=RESUMO!$I$2:$I$100)*(H61>=RESUMO!$K$2:$K$100)*(H61<=RESUMO!$L$2:$L$100), 0)), "R$ ", "")) ))))} -> 22.45 | K61: 0 | L61: =S61/H61 -> 0.0061318919 | M61: 195 | N61: 0.16 | O61: {=IF(M61<12.5, 0, IF(M61<29, 6.25, IF(M61<50, 6.5, IF(M61<79, 6.75, VALUE(SUBSTITUTE( INDEX(RESUMO!$J$2:$J$100, MATCH(1, (D61>=RESUMO!$H$2:$H$100)*(D61<=RESUMO!$I$2:$I$100)*(M61>=RESUMO!$K$2:$K$100)*(M61<=RESUMO!$L$2:$L$100), 0)), "R$ ", "")) ))))} -> 22.45 | P61: 0 | Q61: =U61/M61 -> 0.0014584615 | R61: =(H61-(H61*I61)-J61-(C61*E61)+K61) -> 136.7744 | S61: =R61-(C61-F61) -> 1.1344 | T61: =(M61-(M61*N61)-O61-(C61*E61)+P61) -> 135.9244 | U61: =T61-(C61-F61) -> 0.2844
A62: PHILCO | B62: PHILCO-PLQ1300-VM-127V | C62: 129 | D62: 4 | E62: 0.04 | F62: 0 | G62: 2 | H62: 179 | I62: 0.11 | J62: {=IF(H62<12.5, H62/2, IF(H62<29, 6.25, IF(H62<50, 6.5, IF(H62<79, 6.75, VALUE(SUBSTITUTE( INDEX(RESUMO!$J$2:$J$100, MATCH(1, (D62>=RESUMO!$H$2:$H$100)*(D62<=RESUMO!$I$2:$I$100)*(H62>=RESUMO!$K$2:$K$100)*(H62<=RESUMO!$L$2:$L$100), 0)), "R$ ", "")) ))))} -> 24.25 | K62: 0 | L62: =S62/H62 -> 0.005027933 | M62: 189.9 | N62: 0.16 | O62: {=IF(M62<12.5, 0, IF(M62<29, 6.25, IF(M62<50, 6.5, IF(M62<79, 6.75, VALUE(SUBSTITUTE( INDEX(RESUMO!$J$2:$J$100, MATCH(1, (D62>=RESUMO!$H$2:$H$100)*(D62<=RESUMO!$I$2:$I$100)*(M62>=RESUMO!$K$2:$K$100)*(M62<=RESUMO!$L$2:$L$100), 0)), "R$ ", "")) ))))} -> 24.25 | P62: 0 | Q62: =U62/M62 -> 0.005824118 | R62: =(H62-(H62*I62)-J62-(C62*E62)+K62) -> 129.9 | S62: =R62-(C62-F62) -> 0.9 | T62: =(M62-(M62*N62)-O62-(C62*E62)+P62) -> 130.106 | U62: =T62-(C62-F62) -> 1.106
A63: MONDIAL | B63: MONDIAL-P20-RE-PT-BIV | C63: 91.99 | D63: 0.5 | E63: 0.04 | F63: 0 | G63: 2 | H63: 122.9 | I63: 0.12 | J63: {=IF(H63<12.5, H63/2, IF(H63<29, 6.25, IF(H63<50, 6.5, IF(H63<79, 6.75, VALUE(SUBSTITUTE( INDEX(RESUMO!$J$2:$J$100, MATCH(1, (D63>=RESUMO!$H$2:$H$100)*(D63<=RESUMO!$I$2:$I$100)*(H63>=RESUMO!$K$2:$K$100)*(H63<=RESUMO!$L$2:$L$100), 0)), "R$ ", "")) ))))} -> 17.16 | K63: 0 | L63: =S63/H63 -> -0.038060212 | M63: 154 | N63: 0.17 | O63: {=IF(M63<12.5, 0, IF(M63<29, 6.25, IF(M63<50, 6.5, IF(M63<79, 6.75, VALUE(SUBSTITUTE( INDEX(RESUMO!$J$2:$J$100, MATCH(1, (D63>=RESUMO!$H$2:$H$100)*(D63<=RESUMO!$I$2:$I$100)*(M63>=RESUMO!$K$2:$K$100)*(M63<=RESUMO!$L$2:$L$100), 0)), "R$ ", "")) ))))} -> 19.3 | P63: 0 | Q63: =U63/M63 -> 0.083444156 | R63: =(H63-(H63*I63)-J63-(C63*E63)+K63) -> 87.3124 | S63: =R63-(C63-F63) -> -4.6776 | T63: =(M63-(M63*N63)-O63-(C63*E63)+P63) -> 104.8404 | U63: =T63-(C63-F63) -> 12.8504
A64: PHILCO | B64: PHILCO-CROME-INOX-127V | C64: 137 | D64: 4 | E64: 0.04 | F64: 0 | G64: 2 | H64: 189 | I64: 0.11 | J64: {=IF(H64<12.5, H64/2, IF(H64<29, 6.25, IF(H64<50, 6.5, IF(H64<79, 6.75, VALUE(SUBSTITUTE( INDEX(RESUMO!$J$2:$J$100, MATCH(1, (D64>=RESUMO!$H$2:$H$100)*(D64<=RESUMO!$I$2:$I$100)*(H64>=RESUMO!$K$2:$K$100)*(H64<=RESUMO!$L$2:$L$100), 0)), "R$ ", "")) ))))} -> 24.25 | K64: 0 | L64: =S64/H64 -> 0.0078306878 | M64: 199 | N64: 0.16 | O64: {=IF(M64<12.5, 0, IF(M64<29, 6.25, IF(M64<50, 6.5, IF(M64<79, 6.75, VALUE(SUBSTITUTE( INDEX(RESUMO!$J$2:$J$100, MATCH(1, (D64>=RESUMO!$H$2:$H$100)*(D64<=RESUMO!$I$2:$I$100)*(M64>=RESUMO!$K$2:$K$100)*(M64<=RESUMO!$L$2:$L$100), 0)), "R$ ", "")) ))))} -> 24.25 | P64: 0 | Q64: =U64/M64 -> 0.002160804 | R64: =(H64-(H64*I64)-J64-(C64*E64)+K64) -> 138.48 | S64: =R64-(C64-F64) -> 1.48 | T64: =(M64-(M64*N64)-O64-(C64*E64)+P64) -> 137.43 | U64: =T64-(C64-F64) -> 0.43
A65: PHILCO | B65: PHILCO-PARIS-POWER-PT-127V | C65: 99 | D65: 4 | E65: 0.04 | F65: 0 | G65: 2 | H65: 142 | I65: 0.11 | J65: {=IF(H65<12.5, H65/2, IF(H65<29, 6.25, IF(H65<50, 6.5, IF(H65<79, 6.75, VALUE(SUBSTITUTE( INDEX(RESUMO!$J$2:$J$100, MATCH(1, (D65>=RESUMO!$H$2:$H$100)*(D65<=RESUMO!$I$2:$I$100)*(H65>=RESUMO!$K$2:$K$100)*(H65<=RESUMO!$L$2:$L$100), 0)), "R$ ", "")) ))))} -> 21.56 | K65: 0 | L65: =S65/H65 -> 0.013098592 | M65: 155 | N65: 0.16 | O65: {=IF(M65<12.5, 0, IF(M65<29, 6.25, IF(M65<50, 6.5, IF(M65<79, 6.75, VALUE(SUBSTITUTE( INDEX(RESUMO!$J$2:$J$100, MATCH(1, (D65>=RESUMO!$H$2:$H$100)*(D65<=RESUMO!$I$2:$I$100)*(M65>=RESUMO!$K$2:$K$100)*(M65<=RESUMO!$L$2:$L$100), 0)), "R$ ", "")) ))))} -> 24.25 | P65: 0 | Q65: =U65/M65 -> 0.019290323 | R65: =(H65-(H65*I65)-J65-(C65*E65)+K65) -> 100.86 | S65: =R65-(C65-F65) -> 1.86 | T65: =(M65-(M65*N65)-O65-(C65*E65)+P65) -> 101.99 | U65: =T65-(C65-F65) -> 2.99
...
